function gc() {
    for (let i = 0; i < 10; i++) {
      new ArrayBuffer(1024 * 1024 * 10);
    }
}

function noInline() {
}

function OSRExit() {
}

function ensureArrayStorage() {
}

function fiatInt52(i) {
	return i;
}

function noDFG() {
}

function noOSRExitFuzzing() {
}

function isFinalTier() {
	return true;
}

function transferArrayBuffer() {
}

function fullGC() {
	if (gc !== undefined) 
		gc();
	else
		CollectGarbage();
}

function edenGC() {
	if (gc !== undefined) 
		gc();
	else
		CollectGarbage();
}

function forceGCSlowPaths() {
	if (gc !== undefined) 
		gc();
	else
		CollectGarbage();
}

function noFTL() {

}

function debug(x) {
	console.log(x);
}

function describe(x) {
	console.log(x);
}

function isInt32(i) {
	return (typeof i === "number");
}

function BigInt(i) {
	return i;
}

if (typeof(console) == "undefined") {
    console = {
        log: print
    };
}

if (typeof(gc) == "undefined") {
  gc = function() {
    for (let i = 0; i < 10; i++) {
      new ArrayBuffer(1024 * 1024 * 10);
    }
  }
}

if (typeof(BigInt) == "undefined") {
  BigInt = function (v) { return new Number(v); }
}

if (typeof(BigInt64Array) == "undefined") {
  BigInt64Array = function(v) { return new Array(v); }
}

if (typeof(BigUint64Array) == "undefined") { 
  BigUint64Array = function (v) { return new Array(v); }
}

if (typeof(quit) == "undefined") {
  quit = function() {
  }
}

// This test verifies that we check for out of stack errors from recursively bound functions.
// It should exit without any output.

let expectedException = "RangeError: Maximum call stack size exceeded.";
let actualException = false;

function foo()
{
}

for (var i = 0; i < 6000; ++i) {
    foo = foo.bind(undefined, 1, 2, 3, 4, 5, 6, 7, 8, 9, 10, 11);
    Object.defineProperty(foo, "name", { value: "bar", writable: true, enumerable: true, writable: true });
}

try {
    foo("x", "x", "x", "x", "x", "x", "x", "x", "x", "x", "x", "x", "x", "x", "x", "x", "x", "x", "x", "x", 
        "x", "x", "x", "x", "x", "x", "x", "x", "x", "x", "x", "x", "x", "x", "x", "x", "x", "x", "x", "x", 
        "x", "x", "x", "x", "x", "x", "x", "x", "x", "x", "x", "x", "x", "x", "x", "x", "x", "x", "x", "x", 
        "x", "x", "x", "x", "x", "x", "x", "x", "x", "x", "x", "x", "x", "x", "x", "x", "x", "x", "x", "x", 
        "x", "x", "x", "x", "x", "x", "x", "x", "x", "x", "x", "x", "x", "x", "x", "x", "x", "x", "x", "x", 
        "x", "x", "x", "x", "x", "x", "x", "x", "x", "x", "x", "x", "x", "x", "x", "x", "x", "x", "x", "x", 
        "x", "x", "x", "x", "x", "x", "x", "x", "x", "x", "x", "x", "x", "x", "x", "x", "x", "x", "x", "x", 
        "x", "x", "x", "x", "x", "x", "x", "x", "x", "x", "x", "x", "x", "x", "x", "x", "x", "x", "x", "x", 
        "x", "x", "x", "x", "x", "x", "x", "x", "x", "x", "x", "x", "x", "x", "x", "x", "x", "x", "x", "x", 
        "x", "x", "x", "x", "x", "x", "x", "x", "x", "x", "x", "x", "x", "x", "x", "x", "x", "x", "x", "x");
} catch (e) {
    actualException = e;
}

if (!actualException)
    throw "Expected \"" + expectedException + "\" exception, but no exceptoion was thrown";
else if (actualException != expectedException)
    throw "Expected \"" + expectedException + "\", but got \"" + actualException +"\"";
